<?xml version="1.0" ?>
<mujoco model="sliding_creature">
  <option timestep="0.01"/>
  <default>
    <joint armature="0.1"/>
  </default>
  <asset>
    <material name="color1_limb" rgba="0.3 0.5 0.8 1"/>
    <material name="color_plane" rgba="0.6 0.2 0.2 1"/>
    <material name="color2_limb" rgba="0.9 0.9 0.1 1"/>
  </asset>
  <worldbody>
    <light cutoff="100" diffuse="1 1 1" dir="-0 0 -1.3" directional="true" exponent="1" pos="0 0 1.3" specular=".1 .1 .1"/>
    <geom conaffinity="1" condim="3" material="color_plane" name="floor" pos="0 0 -0.1" size="40 40 0.1" type="plane"/>
    <body name="torso" pos="0 0 0">
      <camera name="track" mode="trackcom" pos="0 -3 3" xyaxes="1 0 0 0 1 1"/>
      <geom density="1000" fromto="1.5 0 0 0.5 0 0" size="0.1" type="capsule" material="color2_limb"/>
      <joint name="free_body_rot" pos="0 0 0" type="free"/>
      <body name="limb1" pos="0.5 0 0">
        <geom density="1000" fromto="0 0 0 -1 0 0" size="0.1" type="capsule" material="color1_limb"/>
        <joint axis="0 0 1" limited="true" name="joint1" pos="0 0 0" range="-100 100" type="hinge"/>
        <body name="limb2" pos="-1 0 0">
          <geom density="1000" fromto="0 0 0 -1 0 0" size="0.1" type="capsule" material="color2_limb"/>
          <joint axis="0 0 1" limited="true" name="joint2" pos="0 0 0" range="-100 100" type="hinge"/>
          <body name="limb3" pos="-1 0 0">
            <geom density="1000" fromto="0 0 0 -1 0 0" size="0.1" type="capsule" material="color1_limb"/>
            <joint axis="0 0 1" limited="true" name="joint3" pos="0 0 0" range="-100 100" type="hinge"/>
            <body name="limb4" pos="-1 0 0">
              <geom density="1000" fromto="0 0 0 -1 0 0" size="0.1" type="capsule" material="color2_limb"/>
              <joint axis="0 0 1" limited="true" name="joint4" pos="0 0 0" range="-100 100" type="hinge"/>
              <body name="limb5" pos="-1 0 0">
                <geom density="1000" fromto="0 0 0 -1 0 0" size="0.1" type="capsule" material="color1_limb"/>
                <joint axis="0 0 1" limited="true" name="joint5" pos="0 0 0" range="-100 100" type="hinge"/>
                <body name="limb6" pos="-1 0 0">
                  <geom density="1000" fromto="0 0 0 -1 0 0" size="0.1" type="capsule" material="color2_limb"/>
                  <joint axis="0 0 1" limited="true" name="joint6" pos="0 0 0" range="-100 100" type="hinge"/>
                </body>
              </body>
            </body>
          </body>
        </body>
      </body>
    </body>
  </worldbody>
  <actuator>
    <motor ctrllimited="true" ctrlrange="-1 1" gear="110" joint="joint1"/>
    <motor ctrllimited="true" ctrlrange="-1 1" gear="484" joint="joint2"/>
    <motor ctrllimited="true" ctrlrange="-1 1" gear="441" joint="joint3"/>
    <motor ctrllimited="true" ctrlrange="-1 1" gear="379" joint="joint4"/>
    <motor ctrllimited="true" ctrlrange="-1 1" gear="496" joint="joint5"/>
    <motor ctrllimited="true" ctrlrange="-1 1" gear="186" joint="joint6"/>
  </actuator>
</mujoco>
