<mujoco model="unnamed_model">
  <option timestep="0.01"/>
  <visual>
    <headlight ambient="0.5 0.5 0.5"/>
  </visual>
  <default>
    <default class="/"/>
  </default>
  <worldbody>
    <light name="//unnamed_light_0" class="/" pos="0 0 3" dir="0 0 -1" diffuse="0.5 0.5 0.5"/>
    <geom name="//unnamed_geom_0" class="/" type="plane" size="50 50 0.10000000000000001" rgba="1 1 0.20000000000000001 1"/>
    <body name="//unnamed_body_0" pos="0 0 20" euler="0 180 0">
      <joint name="//unnamed_joint_0" class="/" type="free" pos="0 0 -0.5" axis="-1 0 0"/>
      <geom name="//unnamed_geom_1" class="/" type="ellipsoid" size="1.5800000000000001 1 0.80000000000000004" rgba="225 0 225 1" mass="1"/>
      <body name="limb1" pos="0 -1 0" euler="30 0 0">
        <geom name="//unnamed_geom_2" class="/" type="cylinder" size="0.10000000000000001 0.29999999999999999" rgba="0 1 0 1" fromto="0 0 0 0 0 1"/>
        <joint name="limb1_joint1" class="/" type="hinge" pos="0 0 1" axis="0 0 1" range="-45 45"/>
        <body name="limb1_part1" pos="0 0 1" euler="0 45 0">
          <geom name="//unnamed_geom_3" class="/" type="cylinder" size="0.10000000000000001 0.29999999999999999" rgba="0 1 0 1" fromto="0 0 0 0 0 1"/>
          <joint name="limb1_joint2" class="/" type="hinge" pos="0 0 1" axis="0 0 1" range="-45 45"/>
          <body name="limb1_part2" pos="0 0 1" euler="0 -90 0">
            <geom name="//unnamed_geom_4" class="/" type="cylinder" size="0.10000000000000001 0.29999999999999999" rgba="0 1 0 1" fromto="0 0 0 0 0 1"/>
            <joint name="limb1_joint3" class="/" type="hinge" pos="0 0 1" axis="0 0 1" range="-45 45"/>
          </body>
        </body>
      </body>
      <body name="limb2" pos="0 1 0" euler="-30 0 0">
        <geom name="//unnamed_geom_5" class="/" type="cylinder" size="0.10000000000000001 0.29999999999999999" rgba="0 1 0 1" fromto="0 0 0 0 0 1"/>
        <joint name="limb2_joint1" class="/" type="hinge" pos="0 0 1" axis="0 0 1" range="-45 45"/>
        <body name="limb2_part1" pos="0 0 1" euler="0 45 0">
          <geom name="//unnamed_geom_6" class="/" type="cylinder" size="0.10000000000000001 0.29999999999999999" rgba="0 1 0 1" fromto="0 0 0 0 0 1"/>
          <joint name="limb2_joint2" class="/" type="hinge" pos="0 0 1" axis="0 0 1" range="-45 45"/>
          <body name="limb2_part2" pos="0 0 1" euler="0 -90 0">
            <geom name="//unnamed_geom_7" class="/" type="cylinder" size="0.10000000000000001 0.29999999999999999" rgba="0 1 0 1" fromto="0 0 0 0 0 1"/>
            <joint name="limb2_joint3" class="/" type="hinge" pos="0 0 1" axis="0 0 1" range="-45 45"/>
          </body>
        </body>
      </body>
      <body name="limb3" pos="1 -0.59999999999999998 0" euler="30 0 0">
        <geom name="//unnamed_geom_8" class="/" type="cylinder" size="0.10000000000000001 0.29999999999999999" rgba="0 1 0 1" fromto="0 0 0 0 0 1"/>
        <joint name="limb3_joint1" class="/" type="hinge" pos="0 0 1" axis="0 0 1" range="-45 45"/>
        <body name="limb3_part1" pos="0 0 1" euler="0 45 0">
          <geom name="//unnamed_geom_9" class="/" type="cylinder" size="0.10000000000000001 0.29999999999999999" rgba="0 1 0 1" fromto="0 0 0 0 0 1"/>
          <joint name="limb3_joint2" class="/" type="hinge" pos="0 0 1" axis="0 0 1" range="-45 45"/>
          <body name="limb3_part2" pos="0 0 1" euler="0 -90 0">
            <geom name="//unnamed_geom_10" class="/" type="cylinder" size="0.10000000000000001 0.29999999999999999" rgba="0 1 0 1" fromto="0 0 0 0 0 1"/>
            <joint name="limb3_joint3" class="/" type="hinge" pos="0 0 1" axis="0 0 1" range="-45 45"/>
          </body>
        </body>
      </body>
      <body name="limb4" pos="1 0.59999999999999998 0" euler="-30 0 0">
        <geom name="//unnamed_geom_11" class="/" type="cylinder" size="0.10000000000000001 0.29999999999999999" rgba="0 1 0 1" fromto="0 0 0 0 0 1"/>
        <joint name="limb4_joint1" class="/" type="hinge" pos="0 0 1" axis="0 0 1" range="-45 45"/>
        <body name="limb4_part1" pos="0 0 1" euler="0 45 0">
          <geom name="//unnamed_geom_12" class="/" type="cylinder" size="0.10000000000000001 0.29999999999999999" rgba="0 1 0 1" fromto="0 0 0 0 0 1"/>
          <joint name="limb4_joint2" class="/" type="hinge" pos="0 0 1" axis="0 0 1" range="-45 45"/>
          <body name="limb4_part2" pos="0 0 1" euler="0 -90 0">
            <geom name="//unnamed_geom_13" class="/" type="cylinder" size="0.10000000000000001 0.29999999999999999" rgba="0 1 0 1" fromto="0 0 0 0 0 1"/>
            <joint name="limb4_joint3" class="/" type="hinge" pos="0 0 1" axis="0 0 1" range="-45 45"/>
          </body>
        </body>
      </body>
      <body name="limb5" pos="-1 -0.59999999999999998 0" euler="30 0 0">
        <geom name="//unnamed_geom_14" class="/" type="cylinder" size="0.10000000000000001 0.29999999999999999" rgba="0 1 0 1" fromto="0 0 0 0 0 1"/>
        <joint name="limb5_joint1" class="/" type="hinge" pos="0 0 1" axis="0 0 1" range="-45 45"/>
        <body name="limb5_part1" pos="0 0 1" euler="0 45 0">
          <geom name="//unnamed_geom_15" class="/" type="cylinder" size="0.10000000000000001 0.29999999999999999" rgba="0 1 0 1" fromto="0 0 0 0 0 1"/>
          <joint name="limb5_joint2" class="/" type="hinge" pos="0 0 1" axis="0 0 1" range="-45 45"/>
          <body name="limb5_part2" pos="0 0 1" euler="0 -90 0">
            <geom name="//unnamed_geom_16" class="/" type="cylinder" size="0.10000000000000001 0.29999999999999999" rgba="0 1 0 1" fromto="0 0 0 0 0 1"/>
            <joint name="limb5_joint3" class="/" type="hinge" pos="0 0 1" axis="0 0 1" range="-45 45"/>
          </body>
        </body>
      </body>
      <body name="limb6" pos="-1 0.59999999999999998 0" euler="-30 0 0">
        <geom name="//unnamed_geom_17" class="/" type="cylinder" size="0.10000000000000001 0.29999999999999999" rgba="0 1 0 1" fromto="0 0 0 0 0 1"/>
        <joint name="limb6_joint1" class="/" type="hinge" pos="0 0 1" axis="0 0 1" range="-45 45"/>
        <body name="limb6_part1" pos="0 0 1" euler="0 45 0">
          <geom name="//unnamed_geom_18" class="/" type="cylinder" size="0.10000000000000001 0.29999999999999999" rgba="0 1 0 1" fromto="0 0 0 0 0 1"/>
          <joint name="limb6_joint2" class="/" type="hinge" pos="0 0 1" axis="0 0 1" range="-45 45"/>
          <body name="limb6_part2" pos="0 0 1" euler="0 -90 0">
            <geom name="//unnamed_geom_19" class="/" type="cylinder" size="0.10000000000000001 0.29999999999999999" rgba="0 1 0 1" fromto="0 0 0 0 0 1"/>
            <joint name="limb6_joint3" class="/" type="hinge" pos="0 0 1" axis="0 0 1" range="-45 45"/>
          </body>
        </body>
      </body>
    </body>
  </worldbody>
  <actuator>
    <motor name="motor_limb1_joint1" class="/" ctrllimited="true" ctrlrange="-45 45" gear="50" joint="limb1_joint1"/>
    <motor name="motor_limb1_joint2" class="/" ctrllimited="true" ctrlrange="-45 45" gear="50" joint="limb1_joint2"/>
    <motor name="motor_limb1_joint3" class="/" ctrllimited="true" ctrlrange="-45 45" gear="50" joint="limb1_joint3"/>
    <motor name="motor_limb2_joint1" class="/" ctrllimited="true" ctrlrange="-45 45" gear="50" joint="limb2_joint1"/>
    <motor name="motor_limb2_joint2" class="/" ctrllimited="true" ctrlrange="-45 45" gear="50" joint="limb2_joint2"/>
    <motor name="motor_limb2_joint3" class="/" ctrllimited="true" ctrlrange="-45 45" gear="50" joint="limb2_joint3"/>
    <motor name="motor_limb3_joint1" class="/" ctrllimited="true" ctrlrange="-45 45" gear="50" joint="limb3_joint1"/>
    <motor name="motor_limb3_joint2" class="/" ctrllimited="true" ctrlrange="-45 45" gear="50" joint="limb3_joint2"/>
    <motor name="motor_limb3_joint3" class="/" ctrllimited="true" ctrlrange="-45 45" gear="50" joint="limb3_joint3"/>
    <motor name="motor_limb4_joint1" class="/" ctrllimited="true" ctrlrange="-45 45" gear="50" joint="limb4_joint1"/>
    <motor name="motor_limb4_joint2" class="/" ctrllimited="true" ctrlrange="-45 45" gear="50" joint="limb4_joint2"/>
    <motor name="motor_limb4_joint3" class="/" ctrllimited="true" ctrlrange="-45 45" gear="50" joint="limb4_joint3"/>
    <motor name="motor_limb5_joint1" class="/" ctrllimited="true" ctrlrange="-45 45" gear="50" joint="limb5_joint1"/>
    <motor name="motor_limb5_joint2" class="/" ctrllimited="true" ctrlrange="-45 45" gear="50" joint="limb5_joint2"/>
    <motor name="motor_limb5_joint3" class="/" ctrllimited="true" ctrlrange="-45 45" gear="50" joint="limb5_joint3"/>
    <motor name="motor_limb6_joint1" class="/" ctrllimited="true" ctrlrange="-45 45" gear="50" joint="limb6_joint1"/>
    <motor name="motor_limb6_joint2" class="/" ctrllimited="true" ctrlrange="-45 45" gear="50" joint="limb6_joint2"/>
    <motor name="motor_limb6_joint3" class="/" ctrllimited="true" ctrlrange="-45 45" gear="50" joint="limb6_joint3"/>
  </actuator>
</mujoco>
