<?xml version="1.0" ?>
<mujoco model="simple_ant">
  <option timestep="0.01"/>
  <default>
    <joint armature="1" damping="1" limited="true"/>
    <geom conaffinity="0" condim="3" density="5.0" friction="1 0.5 0.5" margin="0.01"/>
  </default>
  <worldbody>
    <geom conaffinity="1" condim="3" name="floor" pos="0 0 0" rgba="0.7 0.9 0.7 1" size="40 40 40" type="plane"/>
    <body name="torso" pos="0 0 0.75">
      <geom name="torso_geom" pos="0 0 0" size="0.25" type="sphere" rgba="1 0.5 0.5 1"/>
      <joint armature="0" damping="0" limited="false" margin="0.01" name="root" pos="0 0 0" type="free"/>
      <body name="front_left_leg" pos="0.2 0.2 0">
        <joint axis="0 0 1" name="hip_1" pos="0.0 0.0 0.0" range="-10 10" type="hinge"/>
        <geom fromto="0.0 0.0 0.0 0.2 0.2 0.0" name="front_left_leg_leg_geom" size="0.08" type="capsule"/>
        <body pos="0.2 0.2 0">
          <joint axis="-1 1 0" name="ankle_1" pos="0.0 0.0 0.0" range="5 10" type="hinge"/>
          <geom fromto="0.0 0.0 0.0 0.4 0.4 0.0" name="front_left_leg_ankle_geom" size="0.08" type="capsule"/>
        </body>
      </body>
      <body name="front_right_leg" pos="-0.2 0.2 0">
        <joint axis="0 0 1" name="hip_2" pos="0.0 0.0 0.0" range="-10 10" type="hinge"/>
        <geom fromto="0.0 0.0 0.0 -0.2 0.2 0.0" name="front_right_leg_leg_geom" size="0.08" type="capsule"/>
        <body pos="-0.2 0.2 0">
          <joint axis="1 1 0" name="ankle_2" pos="0.0 0.0 0.0" range="-10 -5" type="hinge"/>
          <geom fromto="0.0 0.0 0.0 -0.4 0.4 0.0" name="front_right_leg_ankle_geom" size="0.08" type="capsule"/>
        </body>
      </body>
      <body name="back_left_leg" pos="0.2 -0.2 0">
        <joint axis="0 0 1" name="hip_3" pos="0.0 0.0 0.0" range="-10 10" type="hinge"/>
        <geom fromto="0.0 0.0 0.0 0.2 -0.2 0.0" name="back_left_leg_leg_geom" size="0.08" type="capsule"/>
        <body pos="0.2 -0.2 0">
          <joint axis="1 1 0" name="ankle_3" pos="0.0 0.0 0.0" range="5 10" type="hinge"/>
          <geom fromto="0.0 0.0 0.0 0.4 -0.4 0.0" name="back_left_leg_ankle_geom" size="0.08" type="capsule"/>
        </body>
      </body>
      <body name="back_right_leg" pos="-0.2 -0.2 0">
        <joint axis="0 0 1" name="hip_4" pos="0.0 0.0 0.0" range="-10 10" type="hinge"/>
        <geom fromto="0.0 0.0 0.0 -0.2 -0.2 0.0" name="back_right_leg_leg_geom" size="0.08" type="capsule"/>
        <body pos="-0.2 -0.2 0">
          <joint axis="-1 1 0" name="ankle_4" pos="0.0 0.0 0.0" range="-10 -5" type="hinge"/>
          <geom fromto="0.0 0.0 0.0 -0.4 -0.4 0.0" name="back_right_leg_ankle_geom" size="0.08" type="capsule"/>
        </body>
      </body>
    </body>
  </worldbody>
  <actuator>
    <motor ctrllimited="true" ctrlrange="-1.0 1.0" joint="hip_1" gear="150"/>
    <motor ctrllimited="true" ctrlrange="-1.0 1.0" joint="ankle_1" gear="150"/>
    <motor ctrllimited="true" ctrlrange="-1.0 1.0" joint="hip_2" gear="150"/>
    <motor ctrllimited="true" ctrlrange="-1.0 1.0" joint="ankle_2" gear="150"/>
    <motor ctrllimited="true" ctrlrange="-1.0 1.0" joint="hip_3" gear="150"/>
    <motor ctrllimited="true" ctrlrange="-1.0 1.0" joint="ankle_3" gear="150"/>
    <motor ctrllimited="true" ctrlrange="-1.0 1.0" joint="hip_4" gear="150"/>
    <motor ctrllimited="true" ctrlrange="-1.0 1.0" joint="ankle_4" gear="150"/>
  </actuator>
</mujoco>
